2018-05-08 14:35:31,867 ERROR: Exception on /index [GET] [in /mnt/c/Users/stacy/OneDrive/Desktop/microblog/venv/lib/python3.5/site-packages/flask/app.py:1761]
Traceback (most recent call last):
  File "/mnt/c/Users/stacy/OneDrive/Desktop/microblog/venv/lib/python3.5/site-packages/flask/app.py", line 2292, in wsgi_app
    response = self.full_dispatch_request()
  File "/mnt/c/Users/stacy/OneDrive/Desktop/microblog/venv/lib/python3.5/site-packages/flask/app.py", line 1815, in full_dispatch_request
    rv = self.handle_user_exception(e)
  File "/mnt/c/Users/stacy/OneDrive/Desktop/microblog/venv/lib/python3.5/site-packages/flask/app.py", line 1718, in handle_user_exception
    reraise(exc_type, exc_value, tb)
  File "/mnt/c/Users/stacy/OneDrive/Desktop/microblog/venv/lib/python3.5/site-packages/flask/_compat.py", line 35, in reraise
    raise value
  File "/mnt/c/Users/stacy/OneDrive/Desktop/microblog/venv/lib/python3.5/site-packages/flask/app.py", line 1813, in full_dispatch_request
    rv = self.dispatch_request()
  File "/mnt/c/Users/stacy/OneDrive/Desktop/microblog/venv/lib/python3.5/site-packages/flask/app.py", line 1799, in dispatch_request
    return self.view_functions[rule.endpoint](**req.view_args)
  File "/mnt/c/Users/stacy/OneDrive/Desktop/microblog/venv/lib/python3.5/site-packages/flask_login/utils.py", line 261, in decorated_view
    return func(*args, **kwargs)
  File "/mnt/c/Users/stacy/OneDrive/Desktop/microblog/app/main/routes.py", line 50, in index
    print(response.status_code)
NameError: name 'response' is not defined
2018-05-08 14:35:46,711 INFO: Microblog startup [in /mnt/c/Users/stacy/OneDrive/Desktop/microblog/app/__init__.py:89]
2018-05-08 14:35:50,901 ERROR: Exception on /index [GET] [in /mnt/c/Users/stacy/OneDrive/Desktop/microblog/venv/lib/python3.5/site-packages/flask/app.py:1761]
Traceback (most recent call last):
  File "/mnt/c/Users/stacy/OneDrive/Desktop/microblog/venv/lib/python3.5/site-packages/flask/app.py", line 2292, in wsgi_app
    response = self.full_dispatch_request()
  File "/mnt/c/Users/stacy/OneDrive/Desktop/microblog/venv/lib/python3.5/site-packages/flask/app.py", line 1815, in full_dispatch_request
    rv = self.handle_user_exception(e)
  File "/mnt/c/Users/stacy/OneDrive/Desktop/microblog/venv/lib/python3.5/site-packages/flask/app.py", line 1718, in handle_user_exception
    reraise(exc_type, exc_value, tb)
  File "/mnt/c/Users/stacy/OneDrive/Desktop/microblog/venv/lib/python3.5/site-packages/flask/_compat.py", line 35, in reraise
    raise value
  File "/mnt/c/Users/stacy/OneDrive/Desktop/microblog/venv/lib/python3.5/site-packages/flask/app.py", line 1813, in full_dispatch_request
    rv = self.dispatch_request()
  File "/mnt/c/Users/stacy/OneDrive/Desktop/microblog/venv/lib/python3.5/site-packages/flask/app.py", line 1799, in dispatch_request
    return self.view_functions[rule.endpoint](**req.view_args)
  File "/mnt/c/Users/stacy/OneDrive/Desktop/microblog/venv/lib/python3.5/site-packages/flask_login/utils.py", line 261, in decorated_view
    return func(*args, **kwargs)
  File "/mnt/c/Users/stacy/OneDrive/Desktop/microblog/app/main/routes.py", line 50, in index
    print(response.status_code)
NameError: name 'response' is not defined
2018-05-08 14:35:58,868 ERROR: Exception on /index [GET] [in /mnt/c/Users/stacy/OneDrive/Desktop/microblog/venv/lib/python3.5/site-packages/flask/app.py:1761]
Traceback (most recent call last):
  File "/mnt/c/Users/stacy/OneDrive/Desktop/microblog/venv/lib/python3.5/site-packages/flask/app.py", line 2292, in wsgi_app
    response = self.full_dispatch_request()
  File "/mnt/c/Users/stacy/OneDrive/Desktop/microblog/venv/lib/python3.5/site-packages/flask/app.py", line 1815, in full_dispatch_request
    rv = self.handle_user_exception(e)
  File "/mnt/c/Users/stacy/OneDrive/Desktop/microblog/venv/lib/python3.5/site-packages/flask/app.py", line 1718, in handle_user_exception
    reraise(exc_type, exc_value, tb)
  File "/mnt/c/Users/stacy/OneDrive/Desktop/microblog/venv/lib/python3.5/site-packages/flask/_compat.py", line 35, in reraise
    raise value
  File "/mnt/c/Users/stacy/OneDrive/Desktop/microblog/venv/lib/python3.5/site-packages/flask/app.py", line 1813, in full_dispatch_request
    rv = self.dispatch_request()
  File "/mnt/c/Users/stacy/OneDrive/Desktop/microblog/venv/lib/python3.5/site-packages/flask/app.py", line 1799, in dispatch_request
    return self.view_functions[rule.endpoint](**req.view_args)
  File "/mnt/c/Users/stacy/OneDrive/Desktop/microblog/venv/lib/python3.5/site-packages/flask_login/utils.py", line 261, in decorated_view
    return func(*args, **kwargs)
  File "/mnt/c/Users/stacy/OneDrive/Desktop/microblog/app/main/routes.py", line 50, in index
    print(response.status_code)
NameError: name 'response' is not defined
2018-05-08 14:38:51,610 ERROR: Exception on /index [GET] [in /mnt/c/Users/stacy/OneDrive/Desktop/microblog/venv/lib/python3.5/site-packages/flask/app.py:1761]
Traceback (most recent call last):
  File "/mnt/c/Users/stacy/OneDrive/Desktop/microblog/venv/lib/python3.5/site-packages/flask/app.py", line 2292, in wsgi_app
    response = self.full_dispatch_request()
  File "/mnt/c/Users/stacy/OneDrive/Desktop/microblog/venv/lib/python3.5/site-packages/flask/app.py", line 1815, in full_dispatch_request
    rv = self.handle_user_exception(e)
  File "/mnt/c/Users/stacy/OneDrive/Desktop/microblog/venv/lib/python3.5/site-packages/flask/app.py", line 1718, in handle_user_exception
    reraise(exc_type, exc_value, tb)
  File "/mnt/c/Users/stacy/OneDrive/Desktop/microblog/venv/lib/python3.5/site-packages/flask/_compat.py", line 35, in reraise
    raise value
  File "/mnt/c/Users/stacy/OneDrive/Desktop/microblog/venv/lib/python3.5/site-packages/flask/app.py", line 1813, in full_dispatch_request
    rv = self.dispatch_request()
  File "/mnt/c/Users/stacy/OneDrive/Desktop/microblog/venv/lib/python3.5/site-packages/flask/app.py", line 1799, in dispatch_request
    return self.view_functions[rule.endpoint](**req.view_args)
  File "/mnt/c/Users/stacy/OneDrive/Desktop/microblog/venv/lib/python3.5/site-packages/flask_login/utils.py", line 261, in decorated_view
    return func(*args, **kwargs)
  File "/mnt/c/Users/stacy/OneDrive/Desktop/microblog/app/main/routes.py", line 50, in index
    print(response.status_code)
NameError: name 'response' is not defined
2018-05-08 14:39:24,673 INFO: Microblog startup [in /mnt/c/Users/stacy/OneDrive/Desktop/microblog/app/__init__.py:89]
2018-05-08 14:39:42,296 INFO: Microblog startup [in /mnt/c/Users/stacy/OneDrive/Desktop/microblog/app/__init__.py:89]
2018-05-08 14:40:18,780 INFO: Microblog startup [in /mnt/c/Users/stacy/OneDrive/Desktop/microblog/app/__init__.py:89]
